[2024-10-11 00:43:51,960][__main__][INFO] - Current working directory: /workspace/assignment-4/Session-4-pytorch-lightning
[2024-10-11 00:43:51,960][__main__][INFO] - Configuration keys: dict_keys(['data', 'paths'])
[2024-10-11 00:43:51,961][__main__][INFO] - Paths configuration: root_dir: /workspace/assignment-4/Session-4-pytorch-lightning
data_dir: /workspace/assignment-4/Session-4-pytorch-lightning/data
log_dir: /workspace/assignment-4/Session-4-pytorch-lightning/logs
output_dir: /workspace/assignment-4/Session-4-pytorch-lightning/outputs/2024-10-11/00-43-51
work_dir: /workspace/assignment-4/Session-4-pytorch-lightning

[2024-10-11 00:43:51,962][__main__][INFO] - Data configuration: _target_: src.datamodules.dog_breed.DogBreedDataModule
gdrive_url: https://drive.google.com/uc?id=1-EJnDNZZkbcW_0Vy9Fy0zcxFZZOGZQWB
dl_path: /workspace/assignment-4/Session-4-pytorch-lightning/data
num_workers: 0
batch_size: 8
train_val_test_split:
- 0.8
- 0.1
- 0.1
seed: 42
pin_memory: false

[2024-10-11 00:43:51,962][__main__][INFO] - Log directory: /workspace/assignment-4/Session-4-pytorch-lightning/logs
[2024-10-11 00:43:51,969][__main__][INFO] - Train Dataset Size: 773
[2024-10-11 00:43:51,969][__main__][INFO] - Validation Dataset Size: 96
[2024-10-11 00:43:51,969][__main__][INFO] - Test Dataset Size: 98
[2024-10-11 00:43:51,969][__main__][INFO] - Class Names: ['Beagle', 'Boxer', 'Bulldog', 'Dachshund', 'German_Shepherd', 'Golden_Retriever', 'Labrador_Retriever', 'Poodle', 'Rottweiler', 'Yorkshire_Terrier']
[2024-10-11 00:43:52,087][timm.models._builder][INFO] - Loading pretrained weights from Hugging Face hub (timm/resnet18.a1_in1k)
[2024-10-11 00:43:52,212][timm.models._hub][INFO] - [timm/resnet18.a1_in1k] Safe alternative available for 'pytorch_model.bin' (as 'model.safetensors'). Loading weights using safetensors.
[2024-10-11 00:43:52,221][timm.models._builder][INFO] - Missing keys (fc.weight, fc.bias) discovered while loading pretrained weights. This is expected if model is being adapted.
[2024-10-11 00:43:52,389][utils.utils][ERROR] - Exception occurred during task execution.
Traceback (most recent call last):
  File "/workspace/assignment-4/Session-4-pytorch-lightning/src/utils/utils.py", line 12, in wrap
    return task_func(*args, **kwargs)
           ^^^^^^^^^^^^^^^^^^^^^^^^^^
  File "/workspace/assignment-4/Session-4-pytorch-lightning/src/train.py", line 93, in train
    trainer.fit(model, datamodule=data_module)
  File "/workspace/assignment-4/Session-4-pytorch-lightning/.venv/lib/python3.12/site-packages/lightning/pytorch/trainer/trainer.py", line 538, in fit
    call._call_and_handle_interrupt(
  File "/workspace/assignment-4/Session-4-pytorch-lightning/.venv/lib/python3.12/site-packages/lightning/pytorch/trainer/call.py", line 47, in _call_and_handle_interrupt
    return trainer_fn(*args, **kwargs)
           ^^^^^^^^^^^^^^^^^^^^^^^^^^^
  File "/workspace/assignment-4/Session-4-pytorch-lightning/.venv/lib/python3.12/site-packages/lightning/pytorch/trainer/trainer.py", line 574, in _fit_impl
    self._run(model, ckpt_path=ckpt_path)
  File "/workspace/assignment-4/Session-4-pytorch-lightning/.venv/lib/python3.12/site-packages/lightning/pytorch/trainer/trainer.py", line 981, in _run
    results = self._run_stage()
              ^^^^^^^^^^^^^^^^^
  File "/workspace/assignment-4/Session-4-pytorch-lightning/.venv/lib/python3.12/site-packages/lightning/pytorch/trainer/trainer.py", line 1023, in _run_stage
    self._run_sanity_check()
  File "/workspace/assignment-4/Session-4-pytorch-lightning/.venv/lib/python3.12/site-packages/lightning/pytorch/trainer/trainer.py", line 1052, in _run_sanity_check
    val_loop.run()
  File "/workspace/assignment-4/Session-4-pytorch-lightning/.venv/lib/python3.12/site-packages/lightning/pytorch/loops/utilities.py", line 178, in _decorator
    return loop_run(self, *args, **kwargs)
           ^^^^^^^^^^^^^^^^^^^^^^^^^^^^^^^
  File "/workspace/assignment-4/Session-4-pytorch-lightning/.venv/lib/python3.12/site-packages/lightning/pytorch/loops/evaluation_loop.py", line 110, in run
    self.setup_data()
  File "/workspace/assignment-4/Session-4-pytorch-lightning/.venv/lib/python3.12/site-packages/lightning/pytorch/loops/evaluation_loop.py", line 166, in setup_data
    dataloaders = _request_dataloader(source)
                  ^^^^^^^^^^^^^^^^^^^^^^^^^^^
  File "/workspace/assignment-4/Session-4-pytorch-lightning/.venv/lib/python3.12/site-packages/lightning/pytorch/trainer/connectors/data_connector.py", line 325, in _request_dataloader
    return data_source.dataloader()
           ^^^^^^^^^^^^^^^^^^^^^^^^
  File "/workspace/assignment-4/Session-4-pytorch-lightning/.venv/lib/python3.12/site-packages/lightning/pytorch/trainer/connectors/data_connector.py", line 292, in dataloader
    return call._call_lightning_datamodule_hook(self.instance.trainer, self.name)
           ^^^^^^^^^^^^^^^^^^^^^^^^^^^^^^^^^^^^^^^^^^^^^^^^^^^^^^^^^^^^^^^^^^^^^^
  File "/workspace/assignment-4/Session-4-pytorch-lightning/.venv/lib/python3.12/site-packages/lightning/pytorch/trainer/call.py", line 189, in _call_lightning_datamodule_hook
    return fn(*args, **kwargs)
           ^^^^^^^^^^^^^^^^^^^
  File "/workspace/assignment-4/Session-4-pytorch-lightning/src/datamodules/dog_breed.py", line 157, in val_dataloader
    return DataLoader(
           ^^^^^^^^^^^
  File "/workspace/assignment-4/Session-4-pytorch-lightning/.venv/lib/python3.12/site-packages/lightning/fabric/utilities/data.py", line 324, in wrapper
    init(obj, *args, **kwargs)
  File "/workspace/assignment-4/Session-4-pytorch-lightning/.venv/lib/python3.12/site-packages/torch/utils/data/dataloader.py", line 255, in __init__
    raise ValueError('persistent_workers option needs num_workers > 0')
ValueError: persistent_workers option needs num_workers > 0
[2024-10-11 00:43:52,392][utils.utils][INFO] - Task completed. Check the logs folder for details.
