[2024-10-06 05:31:20,481][__main__][INFO] - Current working directory: /workspace/Session-4-pytorch-lightning
[2024-10-06 05:31:20,481][__main__][INFO] - Configuration keys: dict_keys(['data', 'paths'])
[2024-10-06 05:31:20,482][__main__][INFO] - Paths configuration: root_dir: /workspace/Session-4-pytorch-lightning
data_dir: /workspace/Session-4-pytorch-lightning/data
log_dir: /workspace/Session-4-pytorch-lightning/logs
output_dir: /workspace/Session-4-pytorch-lightning/outputs/2024-10-06/05-31-20
work_dir: /workspace/Session-4-pytorch-lightning

[2024-10-06 05:31:20,483][__main__][INFO] - Data configuration: _target_: src.datamodules.dog_breed.DogBreedDataModule
gdrive_url: https://drive.google.com/file/d/15Yk-AaufO41Ocs-mnbgBCW46SsQRFlAI/view?usp=sharing
dl_path: /workspace/Session-4-pytorch-lightning/data/dataset/
train_val_test_split:
- 0.8
- 0.1
- 0.1
batch_size: 32
num_workers: 4
pin_memory: false
seed: 42

[2024-10-06 05:31:20,483][__main__][INFO] - Log directory: /workspace/Session-4-pytorch-lightning/logs
[2024-10-06 05:31:20,487][__main__][INFO] - Train Dataset Size: 773
[2024-10-06 05:31:20,487][__main__][INFO] - Validation Dataset Size: 96
[2024-10-06 05:31:20,487][__main__][INFO] - Test Dataset Size: 98
[2024-10-06 05:31:20,488][__main__][INFO] - Class Names: ['Beagle', 'Boxer', 'Bulldog', 'Dachshund', 'German_Shepherd', 'Golden_Retriever', 'Labrador_Retriever', 'Poodle', 'Rottweiler', 'Yorkshire_Terrier']
[2024-10-06 05:31:20,614][timm.models._builder][INFO] - Loading pretrained weights from Hugging Face hub (timm/resnet18.a1_in1k)
[2024-10-06 05:31:20,723][timm.models._hub][INFO] - [timm/resnet18.a1_in1k] Safe alternative available for 'pytorch_model.bin' (as 'model.safetensors'). Loading weights using safetensors.
[2024-10-06 05:31:20,734][timm.models._builder][INFO] - Missing keys (fc.weight, fc.bias) discovered while loading pretrained weights. This is expected if model is being adapted.
[2024-10-06 05:31:20,758][utils.utils][ERROR] - Exception occurred during task execution.
Traceback (most recent call last):
  File "/workspace/Session-4-pytorch-lightning/src/utils/utils.py", line 12, in wrap
    return task_func(*args, **kwargs)
           ^^^^^^^^^^^^^^^^^^^^^^^^^^
  File "/workspace/Session-4-pytorch-lightning/src/train.py", line 89, in train
    print_config_tree(config, resolve=True, save_to_file=True, log_dir=str(log_dir))
  File "/workspace/Session-4-pytorch-lightning/src/utils/rich_utils.py", line 27, in print_config_tree
    for field in print_order:
                 ^^^^^^^^^^^
NameError: name 'print_order' is not defined
[2024-10-06 05:31:20,761][utils.utils][INFO] - Task completed. Check the logs folder for details.
