[2024-10-12 10:13:37,118][__main__][INFO] - Current working directory: /workspace/assignment-4/Session-4-pytorch-lightning
[2024-10-12 10:13:37,118][__main__][INFO] - Configuration keys: dict_keys(['hardware', 'latest_checkpoint', 'paths', 'data', 'model'])
[2024-10-12 10:13:37,122][__main__][INFO] - Using latest checkpoint: {'_target_': 'src.utils.find_latest_checkpoint', 'checkpoint_path': '/workspace/assignment-4/Session-4-pytorch-lightning/logs/runs}'}
[2024-10-12 10:13:37,163][utils.utils][ERROR] - Exception occurred during task execution.
Traceback (most recent call last):
  File "/workspace/assignment-4/Session-4-pytorch-lightning/.venv/lib/python3.12/site-packages/torch/serialization.py", line 564, in _check_seekable
    f.seek(f.tell())
    ^^^^^^
  File "/workspace/assignment-4/Session-4-pytorch-lightning/.venv/lib/python3.12/site-packages/omegaconf/dictconfig.py", line 355, in __getattr__
    self._format_and_raise(
  File "/workspace/assignment-4/Session-4-pytorch-lightning/.venv/lib/python3.12/site-packages/omegaconf/base.py", line 231, in _format_and_raise
    format_and_raise(
  File "/workspace/assignment-4/Session-4-pytorch-lightning/.venv/lib/python3.12/site-packages/omegaconf/_utils.py", line 899, in format_and_raise
    _raise(ex, cause)
  File "/workspace/assignment-4/Session-4-pytorch-lightning/.venv/lib/python3.12/site-packages/omegaconf/_utils.py", line 797, in _raise
    raise ex.with_traceback(sys.exc_info()[2])  # set env var OC_CAUSE=1 for full trace
    ^^^^^^^^^^^^^^^^^^^^^^^^^^^^^^^^^^^^^^^^^^
  File "/workspace/assignment-4/Session-4-pytorch-lightning/.venv/lib/python3.12/site-packages/omegaconf/dictconfig.py", line 351, in __getattr__
    return self._get_impl(
           ^^^^^^^^^^^^^^^
  File "/workspace/assignment-4/Session-4-pytorch-lightning/.venv/lib/python3.12/site-packages/omegaconf/dictconfig.py", line 442, in _get_impl
    node = self._get_child(
           ^^^^^^^^^^^^^^^^
  File "/workspace/assignment-4/Session-4-pytorch-lightning/.venv/lib/python3.12/site-packages/omegaconf/basecontainer.py", line 73, in _get_child
    child = self._get_node(
            ^^^^^^^^^^^^^^^
  File "/workspace/assignment-4/Session-4-pytorch-lightning/.venv/lib/python3.12/site-packages/omegaconf/dictconfig.py", line 480, in _get_node
    raise ConfigKeyError(f"Missing key {key!s}")
omegaconf.errors.ConfigAttributeError: Missing key seek
    full_key: latest_checkpoint.seek
    object_type=dict

During handling of the above exception, another exception occurred:

Traceback (most recent call last):
  File "/workspace/assignment-4/Session-4-pytorch-lightning/src/utils/utils.py", line 12, in wrap
    return task_func(*args, **kwargs)
           ^^^^^^^^^^^^^^^^^^^^^^^^^^
  File "/workspace/assignment-4/Session-4-pytorch-lightning/src/eval.py", line 55, in eval
    model = DogClassifier.load_from_checkpoint(checkpoint_path)
            ^^^^^^^^^^^^^^^^^^^^^^^^^^^^^^^^^^^^^^^^^^^^^^^^^^^
  File "/workspace/assignment-4/Session-4-pytorch-lightning/.venv/lib/python3.12/site-packages/lightning/pytorch/utilities/model_helpers.py", line 125, in wrapper
    return self.method(cls, *args, **kwargs)
           ^^^^^^^^^^^^^^^^^^^^^^^^^^^^^^^^^
  File "/workspace/assignment-4/Session-4-pytorch-lightning/.venv/lib/python3.12/site-packages/lightning/pytorch/core/module.py", line 1582, in load_from_checkpoint
    loaded = _load_from_checkpoint(
             ^^^^^^^^^^^^^^^^^^^^^^
  File "/workspace/assignment-4/Session-4-pytorch-lightning/.venv/lib/python3.12/site-packages/lightning/pytorch/core/saving.py", line 63, in _load_from_checkpoint
    checkpoint = pl_load(checkpoint_path, map_location=map_location)
                 ^^^^^^^^^^^^^^^^^^^^^^^^^^^^^^^^^^^^^^^^^^^^^^^^^^^
  File "/workspace/assignment-4/Session-4-pytorch-lightning/.venv/lib/python3.12/site-packages/lightning/fabric/utilities/cloud_io.py", line 47, in _load
    return torch.load(
           ^^^^^^^^^^^
  File "/workspace/assignment-4/Session-4-pytorch-lightning/.venv/lib/python3.12/site-packages/torch/serialization.py", line 1065, in load
    with _open_file_like(f, 'rb') as opened_file:
         ^^^^^^^^^^^^^^^^^^^^^^^^
  File "/workspace/assignment-4/Session-4-pytorch-lightning/.venv/lib/python3.12/site-packages/torch/serialization.py", line 473, in _open_file_like
    return _open_buffer_reader(name_or_buffer)
           ^^^^^^^^^^^^^^^^^^^^^^^^^^^^^^^^^^^
  File "/workspace/assignment-4/Session-4-pytorch-lightning/.venv/lib/python3.12/site-packages/torch/serialization.py", line 458, in __init__
    _check_seekable(buffer)
  File "/workspace/assignment-4/Session-4-pytorch-lightning/.venv/lib/python3.12/site-packages/torch/serialization.py", line 567, in _check_seekable
    raise_err_msg(["seek", "tell"], e)
  File "/workspace/assignment-4/Session-4-pytorch-lightning/.venv/lib/python3.12/site-packages/torch/serialization.py", line 560, in raise_err_msg
    raise type(e)(msg)
omegaconf.errors.ConfigAttributeError: Missing key seek
    full_key: latest_checkpoint.seek
    object_type=dict. You can only torch.load from a file that is seekable. Please pre-load the data into a buffer like io.BytesIO and try to load from it instead.
[2024-10-12 10:13:37,165][utils.utils][INFO] - Task completed. Check the logs folder for details.
