[2024-10-06 05:04:34,604][__main__][INFO] - Current working directory: /workspace/Session-4-pytorch-lightning
[2024-10-06 05:04:34,604][__main__][INFO] - Configuration keys: dict_keys(['data', 'paths'])
[2024-10-06 05:04:34,605][__main__][INFO] - Paths configuration: root_dir: /workspace/Session-4-pytorch-lightning
data_dir: /workspace/Session-4-pytorch-lightning/data/
log_dir: /workspace/Session-4-pytorch-lightning/logs/
output_dir: /workspace/Session-4-pytorch-lightning/outputs/2024-10-06/05-04-34
work_dir: /workspace/Session-4-pytorch-lightning

[2024-10-06 05:04:34,605][__main__][INFO] - Data configuration: _target_: src.datamodules.dog_breed.DogBreedDataModule
gdrive_url: https://drive.google.com/file/d/15Yk-AaufO41Ocs-mnbgBCW46SsQRFlAI/view?usp=sharing
dl_path: /workspace/Session-4-pytorch-lightning/data//dataset/
train_val_test_split:
- 0.8
- 0.1
- 0.1
batch_size: 32
num_workers: 4
pin_memory: false
seed: 42

[2024-10-06 05:04:41,853][utils.utils][ERROR] - Exception occurred during task execution.
Traceback (most recent call last):
  File "/workspace/Session-4-pytorch-lightning/src/utils/utils.py", line 12, in wrap
    return task_func(*args, **kwargs)
           ^^^^^^^^^^^^^^^^^^^^^^^^^^
  File "/workspace/Session-4-pytorch-lightning/src/train.py", line 50, in train
    data_module.setup()
  File "/workspace/Session-4-pytorch-lightning/src/datamodules/dog_breed.py", line 120, in setup
    self.num_classes = len(self._class_names)
    ^^^^^^^^^^^^^^^^
AttributeError: property 'num_classes' of 'DogBreedDataModule' object has no setter
[2024-10-06 05:04:41,853][utils.utils][INFO] - Task completed. Check the logs folder for details.
