[2024-10-12 10:36:44,692][__main__][INFO] - Current working directory: /workspace/assignment-4/Session-4-pytorch-lightning
[2024-10-12 10:36:44,692][__main__][INFO] - Configuration keys: dict_keys(['hardware', 'latest_checkpoint', 'paths', 'data', 'model'])
[2024-10-12 10:36:44,693][__main__][INFO] - latest_checkpoint config: {'_target_': 'src.utils.checkpoint_utils.find_latest_checkpoint', 'dir': '/workspace/assignment-4/Session-4-pytorch-lightning/logs/runs'}
[2024-10-12 10:36:44,693][src.utils.checkpoint_utils][INFO] - Searching for checkpoints in: /workspace/assignment-4/Session-4-pytorch-lightning/logs/runs
[2024-10-12 10:36:44,694][src.utils.checkpoint_utils][INFO] - Latest run directory: /workspace/assignment-4/Session-4-pytorch-lightning/logs/runs/2024-10-12_10-33-50
[2024-10-12 10:36:44,694][src.utils.checkpoint_utils][INFO] - Latest checkpoint file: /workspace/assignment-4/Session-4-pytorch-lightning/logs/runs/2024-10-12_10-33-50/checkpoints/last.ckpt
[2024-10-12 10:36:44,694][__main__][INFO] - Resolved checkpoint path: /workspace/assignment-4/Session-4-pytorch-lightning/logs/runs/2024-10-12_10-33-50/checkpoints/last.ckpt
[2024-10-12 10:36:44,987][timm.models._builder][INFO] - Loading pretrained weights from Hugging Face hub (timm/resnet18.a1_in1k)
[2024-10-12 10:36:45,100][timm.models._hub][INFO] - [timm/resnet18.a1_in1k] Safe alternative available for 'pytorch_model.bin' (as 'model.safetensors'). Loading weights using safetensors.
[2024-10-12 10:36:45,110][timm.models._builder][INFO] - Missing keys (fc.weight, fc.bias) discovered while loading pretrained weights. This is expected if model is being adapted.
[2024-10-12 10:36:45,145][utils.utils][ERROR] - Exception occurred during task execution.
Traceback (most recent call last):
  File "/workspace/assignment-4/Session-4-pytorch-lightning/src/utils/utils.py", line 12, in wrap
    return task_func(*args, **kwargs)
           ^^^^^^^^^^^^^^^^^^^^^^^^^^
  File "/workspace/assignment-4/Session-4-pytorch-lightning/src/eval.py", line 66, in eval
    for batch in data_module.test_dataloader():
                 ^^^^^^^^^^^
NameError: name 'data_module' is not defined
[2024-10-12 10:36:45,149][utils.utils][INFO] - Task completed. Check the logs folder for details.
